Workbook

Sheet Assumptions
A1: NutriSync — Assumptions (All blue cells are inputs. Change here; all scenario sheets update.)
A2: Category | B2: Assumption | C2: Conservative | D2: Realistic | E2: Ambitious
A3: PRICING
A4: PRICING | B4: B2C basic price/mo (€) | C4: 4.99 | D4: 4.99 | E4: 4.99
A5: PRICING | B5: B2C premium price/mo (€) — launches M13 | C5: 12.99 | D5: 12.99 | E5: 12.99
A6: PRICING | B6: B2B price Y1 (€/employee/mo) | C6: 3.99 | D6: 3.99 | E6: 3.99
A7: PRICING | B7: B2B price Y2+ renewal (€/employee/mo) | C7: 5.99 | D7: 5.99 | E7: 5.99
A8: FUNNEL
A9: FUNNEL | B9: New organic free users M1 | C9: 320 | D9: 350 | E9: 420
A10: FUNNEL | B10: Organic new-user growth rate (%/mo) | C10: 0.18 | D10: 0.19 | E10: 0.2
A11: FUNNEL | B11: Free-to-paid conversion (one-off % per month new free users) | C11: 0.12 | D11: 0.14 | E11: 0.13
A12: FUNNEL | B12: Paid social budget Y1 (€/mo, from M4) | C12: 9000 | D12: 11000 | E12: 14000
A13: FUNNEL | B13: Paid social budget Y2 (€/mo) | C13: 18000 | D13: 28000 | E13: 25000
A14: FUNNEL | B14: Paid social budget Y3 (€/mo) | C14: 18000 | D14: 21000 | E14: 38000
A15: FUNNEL | B15: CAC — paid social Y1 (€/paying subscriber) | C15: 20 | D15: 15 | E15: 12
A16: FUNNEL | B16: CAC — paid social Y2+ (€/paying subscriber) | C16: 24 | D16: 18 | E16: 14
A17: CHURN
A18: CHURN | B18: Base monthly churn Y1 (average fitness app = 9.2%) | C18: 0.09 | D18: 0.08 | E18: 0.07
A19: CHURN | B19: Base monthly churn Y2 | C19: 0.08 | D19: 0.07 | E19: 0.06
A20: CHURN | B20: Base monthly churn Y3 | C20: 0.065 | D20: 0.055 | E20: 0.05
A21: CHURN | B21: Wearable adoption ramp (%-pts/mo from M4) | C21: 0.015 | D21: 0.02 | E21: 0.025
A22: CHURN | B22: Wearable adoption cap (% of paid users) | C22: 0.3 | D22: 0.4 | E22: 0.5
A23: CHURN | B23: Wearable churn reduction (vs base; 30–40% defensible) | C23: 0.3 | D23: 0.35 | E23: 0.4
A24: PREMIUM
A25: PREMIUM | B25: Premium launch month | C25: 13 | D25: 13 | E25: 12
A26: PREMIUM | B26: Premium upgrade rate (%/mo of basic base, post-launch) | C26: 0.0075 | D26: 0.01 | E26: 0.015
A27: PREMIUM | B27: Premium monthly churn | C27: 0.04 | D27: 0.035 | E27: 0.03
A28: B2B
A29: B2B | B29: New B2B contracts/mo Y1 (from M6) | C29: 1.5 | D29: 1.7 | E29: 2
A30: B2B | B30: New B2B contracts/mo Y2 | C30: 3 | D30: 1.7 | E30: 5.3
A31: B2B | B31: New B2B contracts/mo Y3 | C31: 3.5 | D31: 3.6 | E31: 3.6
A32: B2B | B32: Avg employees per B2B contract | C32: 120 | D32: 150 | E32: 175
A33: B2B | B33: B2B annual logo churn | C33: 0.2 | D33: 0.18 | E33: 0.15
A34: OTHER REV
A35: OTHER REV | B35: Events net €/mo Y1 (from M3) | C35: 500 | D35: 750 | E35: 1000
A36: OTHER REV | B36: Events net €/mo Y2 | C36: 1000 | D36: 1500 | E36: 2000
A37: OTHER REV | B37: Events net €/mo Y3 | C37: 1500 | D37: 2000 | E37: 3000
A38: OTHER REV | B38: Brand partnerships €/mo Y3 (conservative = 0) | C38: 0 | D38: 2000 | E38: 3500
A39: OTHER REV | B39: Clinical referral fee (€/contract signed/mo, from M6) | C39: 300 | D39: 400 | E39: 500
A40: FEES
...

Sheet Conservative
A1: NutriSync — Conservative Scenario | All inputs from Assumptions sheet | Blue = inputs, Black = formulas
A2: METRIC | B2: M1 | C2: M2 | D2: M3 | E2: M4 | F2: M5 | G2: M6 | H2: M7 | I2: M8 | J2: M9 | K2: M10 | L2: M11 | M2: M12 | N2: M13 | O2: M14 | P2: M15 | Q2: M16 | R2: M17 | S2: M18 | T2: M19 | U2: M20 | V2: M21 | W2: M22 | X2: M23 | Y2: M24 | Z2: M25 | AA2: M26 | AB2: M27 | AC2: M28 | AD2: M29 | AE2: M30 | AF2: M31 | AG2: M32 | AH2: M33 | AI2: M34 | AJ2: M35 | AK2: M36 | AL2: Y1 Total | AM2: Y2 Total | AN2: Y3 Total | AO2: Notes / Formula
A3: Year | B3: 1 | C3: 1 | D3: 1 | E3: 1 | F3: 1 | G3: 1 | H3: 1 | I3: 1 | J3: 1 | K3: 1 | L3: 1 | M3: 1 | N3: 2 | O3: 2 | P3: 2 | Q3: 2 | R3: 2 | S3: 2 | T3: 2 | U3: 2 | V3: 2 | W3: 2 | X3: 2 | Y3: 2 | Z3: 3 | AA3: 3 | AB3: 3 | AC3: 3 | AD3: 3 | AE3: 3 | AF3: 3 | AG3: 3 | AH3: 3 | AI3: 3 | AJ3: 3 | AK3: 3
A4: SECTION 1 — USER PROJECTIONS
A5: New organic free users/mo | B5: =Assumptions!C9 -> 320 | C5: =B5*(1+Assumptions!C10) -> 377.6 | D5: =C5*(1+Assumptions!C10) -> 445.568 | E5: =D5*(1+Assumptions!C10) -> 525.77024 | F5: =E5*(1+Assumptions!C10) -> 620.40888 | G5: =F5*(1+Assumptions!C10) -> 732.08248 | H5: =G5*(1+Assumptions!C10) -> 863.85733 | I5: =H5*(1+Assumptions!C10) -> 1019.3516 | J5: =I5*(1+Assumptions!C10) -> 1202.8349 | K5: =J5*(1+Assumptions!C10) -> 1419.3452 | L5: =K5*(1+Assumptions!C10) -> 1674.8274 | M5: =L5*(1+Assumptions!C10) -> 1976.2963 | N5: =M5*(1+Assumptions!C10) -> 2332.0296 | O5: =N5*(1+Assumptions!C10) -> 2751.795 | P5: =O5*(1+Assumptions!C10) -> 3247.1181 | Q5: =P5*(1+Assumptions!C10) -> 3831.5993 | R5: =Q5*(1+Assumptions!C10) -> 4521.2872 | S5: =R5*(1+Assumptions!C10) -> 5335.1189 | T5: =S5*(1+Assumptions!C10) -> 6295.4403 | U5: =T5*(1+Assumptions!C10) -> 7428.6196 | V5: =U5*(1+Assumptions!C10) -> 8765.7711 | W5: =V5*(1+Assumptions!C10) -> 10343.61 | X5: =W5*(1+Assumptions!C10) -> 12205.46 | Y5: =X5*(1+Assumptions!C10) -> 14402.442 | Z5: =Y5*(1+Assumptions!C10) -> 16994.882 | AA5: =Z5*(1+Assumptions!C10) -> 20053.961 | AB5: =AA5*(1+Assumptions!C10) -> 23663.674 | AC5: =AB5*(1+Assumptions!C10) -> 27923.135 | AD5: =AC5*(1+Assumptions!C10) -> 32949.299 | AE5: =AD5*(1+Assumptions!C10) -> 38880.173 | AF5: =AE5*(1+Assumptions!C10) -> 45878.604 | AG5: =AF5*(1+Assumptions!C10) -> 54136.753 | AH5: =AG5*(1+Assumptions!C10) -> 63881.369 | AI5: =AH5*(1+Assumptions!C10) -> 75380.015 | AJ5: =AI5*(1+Assumptions!C10) -> 88948.418 | AK5: =AJ5*(1+Assumptions!C10) -> 104959.13 | AL5: =SUM(B5:M5) -> 11177.942 | AM5: =SUM(N5:Y5) -> 81460.291 | AN5: =SUM(Z5:AK5) -> 593649.42 | AO5: Compounds from M1 at organic growth rate.
A6: → New paid: organic conversion (one-off per month's new free users) | B6: =B5*Assumptions!C11 -> 38.4 | C6: =C5*Assumptions!C11 -> 45.312 | D6: =D5*Assumptions!C11 -> 53.46816 | E6: =E5*Assumptions!C11 -> 63.092429 | F6: =F5*Assumptions!C11 -> 74.449066 | G6: =G5*Assumptions!C11 -> 87.849898 | H6: =H5*Assumptions!C11 -> 103.66288 | I6: =I5*Assumptions!C11 -> 122.3222 | J6: =J5*Assumptions!C11 -> 144.34019 | K6: =K5*Assumptions!C11 -> 170.32143 | L6: =L5*Assumptions!C11 -> 200.97929 | M6: =M5*Assumptions!C11 -> 237.15556 | N6: =N5*Assumptions!C11 -> 279.84356 | O6: =O5*Assumptions!C11 -> 330.2154 | P6: =P5*Assumptions!C11 -> 389.65417 | Q6: =Q5*Assumptions!C11 -> 459.79192 | R6: =R5*Assumptions!C11 -> 542.55446 | S6: =S5*Assumptions!C11 -> 640.21427 | T6: =T5*Assumptions!C11 -> 755.45284 | U6: =U5*Assumptions!C11 -> 891.43435 | V6: =V5*Assumptions!C11 -> 1051.8925 | W6: =W5*Assumptions!C11 -> 1241.2332 | X6: =X5*Assumptions!C11 -> 1464.6552 | Y6: =Y5*Assumptions!C11 -> 1728.2931 | Z6: =Z5*Assumptions!C11 -> 2039.3858 | AA6: =AA5*Assumptions!C11 -> 2406.4753 | AB6: =AB5*Assumptions!C11 -> 2839.6408 | AC6: =AC5*Assumptions!C11 -> 3350.7762 | AD6: =AD5*Assumptions!C11 -> 3953.9159 | AE6: =AE5*Assumptions!C11 -> 4665.6208 | AF6: =AF5*Assumptions!C11 -> 5505.4325 | AG6: =AG5*Assumptions!C11 -> 6496.4104 | AH6: =AH5*Assumptions!C11 -> 7665.7642 | AI6: =AI5*Assumptions!C11 -> 9045.6018 | AJ6: =AJ5*Assumptions!C11 -> 10673.81 | AK6: =AK5*Assumptions!C11 -> 12595.096 | AL6: =SUM(B6:M6) -> 1341.3531 | AM6: =SUM(N6:Y6) -> 9775.2349 | AN6: =SUM(Z6:AK6) -> 71237.93 | AO6: 5–8% one-off per month (NOT monthly to pool). Benchmark: RevenueCat H&F median 6.9%.
A7: → New paid: paid social (budget ÷ CAC) | B7: =0 -> 0 | C7: =0 -> 0 | D7: =0 -> 0 | E7: =Assumptions!C12/Assumptions!C15 -> 450 | F7: =Assumptions!C12/Assumptions!C15 -> 450 | G7: =Assumptions!C12/Assumptions!C15 -> 450 | H7: =Assumptions!C12/Assumptions!C15 -> 450 | I7: =Assumptions!C12/Assumptions!C15 -> 450 | J7: =Assumptions!C12/Assumptions!C15 -> 450 | K7: =Assumptions!C12/Assumptions!C15 -> 450 | L7: =Assumptions!C12/Assumptions!C15 -> 450 | M7: =Assumptions!C12/Assumptions!C15 -> 450 | N7: =Assumptions!C13/Assumptions!C16 -> 750 | O7: =Assumptions!C13/Assumptions!C16 -> 750 | P7: =Assumptions!C13/Assumptions!C16 -> 750 | Q7: =Assumptions!C13/Assumptions!C16 -> 750 | R7: =Assumptions!C13/Assumptions!C16 -> 750 | S7: =Assumptions!C13/Assumptions!C16 -> 750 | T7: =Assumptions!C13/Assumptions!C16 -> 750 | U7: =Assumptions!C13/Assumptions!C16 -> 750 | V7: =Assumptions!C13/Assumptions!C16 -> 750 | W7: =Assumptions!C13/Assumptions!C16 -> 750 | X7: =Assumptions!C13/Assumptions!C16 -> 750 | Y7: =Assumptions!C13/Assumptions!C16 -> 750 | Z7: =Assumptions!C14/Assumptions!C16 -> 750 | AA7: =Assumptions!C14/Assumptions!C16 -> 750 | AB7: =Assumptions!C14/Assumptions!C16 -> 750 | AC7: =Assumptions!C14/Assumptions!C16 -> 750 | AD7: =Assumptions!C14/Assumptions!C16 -> 750 | AE7: =Assumptions!C14/Assumptions!C16 -> 750 | AF7: =Assumptions!C14/Assumptions!C16 -> 750 | AG7: =Assumptions!C14/Assumptions!C16 -> 750 | AH7: =Assumptions!C14/Assumptions!C16 -> 750 | AI7: =Assumptions!C14/Assumptions!C16 -> 750 | AJ7: =Assumptions!C14/Assumptions!C16 -> 750 | AK7: =Assumptions!C14/Assumptions!C16 -> 750 | AL7: =SUM(B7:M7) -> 4050 | AM7: =SUM(N7:Y7) -> 9000 | AN7: =SUM(Z7:AK7) -> 9000 | AO7: Budget / CAC. CAC corrected: €20 Y1 conservative (not €6–8; install alone $3.70–4.70).
A8: % of paid users with wearable connected | B8: =0 -> 0 | C8: =0 -> 0 | D8: =0 -> 0 | E8: =MIN(Assumptions!C22,1*Assumptions!C21) -> 0.015 | F8: =MIN(Assumptions!C22,2*Assumptions!C21) -> 0.03 | G8: =MIN(Assumptions!C22,3*Assumptions!C21) -> 0.045 | H8: =MIN(Assumptions!C22,4*Assumptions!C21) -> 0.06 | I8: =MIN(Assumptions!C22,5*Assumptions!C21) -> 0.075 | J8: =MIN(Assumptions!C22,6*Assumptions!C21) -> 0.09 | K8: =MIN(Assumptions!C22,7*Assumptions!C21) -> 0.105 | L8: =MIN(Assumptions!C22,8*Assumptions!C21) -> 0.12 | M8: =MIN(Assumptions!C22,9*Assumptions!C21) -> 0.135 | N8: =MIN(Assumptions!C22,10*Assumptions!C21) -> 0.15 | O8: =MIN(Assumptions!C22,11*Assumptions!C21) -> 0.165 | P8: =MIN(Assumptions!C22,12*Assumptions!C21) -> 0.18 | Q8: =MIN(Assumptions!C22,13*Assumptions!C21) -> 0.195 | R8: =MIN(Assumptions!C22,14*Assumptions!C21) -> 0.21 | S8: =MIN(Assumptions!C22,15*Assumptions!C21) -> 0.225 | T8: =MIN(Assumptions!C22,16*Assumptions!C21) -> 0.24 | U8: =MIN(Assumptions!C22,17*Assumptions!C21) -> 0.255 | V8: =MIN(Assumptions!C22,18*Assumptions!C21) -> 0.27 | W8: =MIN(Assumptions!C22,19*Assumptions!C21) -> 0.285 | X8: =MIN(Assumptions!C22,20*Assumptions!C21) -> 0.3 | Y8: =MIN(Assumptions!C22,21*Assumptions!C21) -> 0.3 | Z8: =MIN(Assumptions!C22,22*Assumptions!C21) -> 0.3 | AA8: =MIN(Assumptions!C22,23*Assumptions!C21) -> 0.3 | AB8: =MIN(Assumptions!C22,24*Assumptions!C21) -> 0.3 | AC8: =MIN(Assumptions!C22,25*Assumptions!C21) -> 0.3 | AD8: =MIN(Assumptions!C22,26*Assumptions!C21) -> 0.3 | AE8: =MIN(Assumptions!C22,27*Assumptions!C21) -> 0.3 | AF8: =MIN(Assumptions!C22,28*Assumptions!C21) -> 0.3 | AG8: =MIN(Assumptions!C22,29*Assumptions!C21) -> 0.3 | AH8: =MIN(Assumptions!C22,30*Assumptions!C21) -> 0.3 | AI8: =MIN(Assumptions!C22,31*Assumptions!C21) -> 0.3 | AJ8: =MIN(Assumptions!C22,32*Assumptions!C21) -> 0.3 | AK8: =MIN(Assumptions!C22,33*Assumptions!C21) -> 0.3 | AL8: =M8 -> 0.135 | AM8: =Y8 -> 0.3 | AN8: =AK8 -> 0.3 | AO8: Ramps +1.5–2.5%pts/mo from M4; capped at adoption ceiling.
A9: Blended monthly churn (wearable-adjusted) | B9: =Assumptions!C18*(1-B8*Assumptions!C23) -> 0.09 | C9: =Assumptions!C18*(1-C8*Assumptions!C23) -> 0.09 | D9: =Assumptions!C18*(1-D8*Assumptions!C23) -> 0.09 | E9: =Assumptions!C18*(1-E8*Assumptions!C23) -> 0.089595 | F9: =Assumptions!C18*(1-F8*Assumptions!C23) -> 0.08919 | G9: =Assumptions!C18*(1-G8*Assumptions!C23) -> 0.088785 | H9: =Assumptions!C18*(1-H8*Assumptions!C23) -> 0.08838 | I9: =Assumptions!C18*(1-I8*Assumptions!C23) -> 0.087975 | J9: =Assumptions!C18*(1-J8*Assumptions!C23) -> 0.08757 | K9: =Assumptions!C18*(1-K8*Assumptions!C23) -> 0.087165 | L9: =Assumptions!C18*(1-L8*Assumptions!C23) -> 0.08676 | M9: =Assumptions!C18*(1-M8*Assumptions!C23) -> 0.086355 | N9: =Assumptions!C19*(1-N8*Assumptions!C23) -> 0.0764 | O9: =Assumptions!C19*(1-O8*Assumptions!C23) -> 0.07604 | P9: =Assumptions!C19*(1-P8*Assumptions!C23) -> 0.07568 | Q9: =Assumptions!C19*(1-Q8*Assumptions!C23) -> 0.07532 | R9: =Assumptions!C19*(1-R8*Assumptions!C23) -> 0.07496 | S9: =Assumptions!C19*(1-S8*Assumptions!C23) -> 0.0746 | T9: =Assumptions!C19*(1-T8*Assumptions!C23) -> 0.07424 | U9: =Assumptions!C19*(1-U8*Assumptions!C23) -> 0.07388 | V9: =Assumptions!C19*(1-V8*Assumptions!C23) -> 0.07352 | W9: =Assumptions!C19*(1-W8*Assumptions!C23) -> 0.07316 | X9: =Assumptions!C19*(1-X8*Assumptions!C23) -> 0.0728 | Y9: =Assumptions!C19*(1-Y8*Assumptions!C23) -> 0.0728 | Z9: =Assumptions!C20*(1-Z8*Assumptions!C23) -> 0.05915 | AA9: =Assumptions!C20*(1-AA8*Assumptions!C23) -> 0.05915 | AB9: =Assumptions!C20*(1-AB8*Assumptions!C23) -> 0.05915 | AC9: =Assumptions!C20*(1-AC8*Assumptions!C23) -> 0.05915 | AD9: =Assumptions!C20*(1-AD8*Assumptions!C23) -> 0.05915 | AE9: =Assumptions!C20*(1-AE8*Assumptions!C23) -> 0.05915 | AF9: =Assumptions!C20*(1-AF8*Assumptions!C23) -> 0.05915 | AG9: =Assumptions!C20*(1-AG8*Assumptions!C23) -> 0.05915 | AH9: =Assumptions!C20*(1-AH8*Assumptions!C23) -> 0.05915 | AI9: =Assumptions!C20*(1-AI8*Assumptions!C23) -> 0.05915 | AJ9: =Assumptions!C20*(1-AJ8*Assumptions!C23) -> 0.05915 | AK9: =Assumptions!C20*(1-AK8*Assumptions!C23) -> 0.05915 | AL9: =AVERAGE(B9:M9) -> 0.08848125 | AM9: =AVERAGE(N9:Y9) -> 0.07445 | AN9: =AVERAGE(Z9:AK9) -> 0.05915 | AO9: base × (1 − wearable% × reduction_factor).
A10: Premium upgrades from basic (M13+) | B10: =0 -> 0 | C10: =0 -> 0 | D10: =0 -> 0 | E10: =0 -> 0 | F10: =0 -> 0 | G10: =0 -> 0 | H10: =0 -> 0 | I10: =0 -> 0 | ... M10: =0 -> 0 | N10: =M11*Assumptions!C26 -> 29.167483 | O10: =N11*Assumptions!C26 -> 34.444158 | P10: =O11*Assumptions!C26 -> 39.668308 | Q10: =P11*Assumptions!C26 -> 44.916105 | R10: =Q11*Assumptions!C26 -> 50.269592 | S10: =R11*Assumptions!C26 -> 55.81852 | T10: =S11*Assumptions!C26 -> 61.662427 | U10: =T11*Assumptions!C26 -> 67.913036 | V10: =U11*Assumptions!C26 -> 74.697031 | W10: =V11*Assumptions!C26 -> 82.159271 | X10: =W11*Assumptions!C26 -> 90.466553 | Y10: =X11*Assumptions!C26 -> 99.812003 | Z10: =Y11*Assumptions!C26 -> 110.3843 | AA10: =Z11*Assumptions!C26 -> 123.94758 | AB10: =AA11*Assumptions!C26 -> 139.36004 | AC10: =AB11*Assumptions!C26 -> 156.994 | AD10: =AC11*Assumptions!C26 -> 177.28617 | AE10: =AD11*Assumptions!C26 -> 200.74941 | AF10: =AE11*Assumptions!C26 -> 227.98662 | AG10: =AF11*Assumptions!C26 -> 259.70706 | AH10: =AG11*Assumptions!C26 -> 296.74566 | AI10: =AH11*Assumptions!C26 -> 340.08579 | AJ10: =AI11*Assumptions!C26 -> 390.88609 | AK10: =AJ11*Assumptions!C26 -> 450.51211 | AL10: =SUM(B10:M10) -> 0 | AM10: =SUM(N10:Y10) -> 730.99449 | AN10: =SUM(Z10:AK10) -> 2874.6448 | AO10: 0.75–1.5%/mo of basic base (corrected from 4–8%/mo compounding).
A11: B2C basic subscribers (EoM) | B11: =B6+B7 -> 38.4 | C11: =B11*(1-C9)-C10+C6+C7 -> 80.256 | D11: =C11*(1-D9)-D10+D6+D7 -> 126.50112 | E11: =D11*(1-E9)-E10+E6+E7 -> 628.25968 | F11: =E11*(1-F9)-F10+F6+F7 -> 1096.6743 | G11: =F11*(1-G9)-G10+G6+G7 -> 1537.1559 | H11: =G11*(1-H9)-H10+H6+H7 -> 1954.965 | I11: =H11*(1-I9)-I10+I6+I7 -> 2355.2991 | J11: =I11*(1-J9)-J10+J6+J7 -> 2743.3858 | ... AK11: =AJ11*(1-AK9)-AK10+AK6+AK7 -> 69409.826 | AL11: =M11 -> 3888.9977 | AM11: =Y11 -> 14717.906 | AN11: =AK11 -> 69409.826 | AO11: Prior × (1-churn) - upgrades + new converts.
A12: B2C premium subscribers (EoM — upgrade from basic, not added on top) | B12: =0 -> 0 | C12: =0 -> 0 | D12: =0 -> 0 | E12: =0 -> 0 | F12: =0 -> 0 | G12: =0 -> 0 | H12: =0 -> 0 | I12: =0 -> 0 | ... M12: =0 -> 0 | N12: =N10 -> 29.167483 | O12: =N12*(1-Assumptions!C27)+O10 -> 62.444941 | P12: =O12*(1-Assumptions!C27)+P10 -> 99.615452 | Q12: =P12*(1-Assumptions!C27)+Q10 -> 140.54694 | R12: =Q12*(1-Assumptions!C27)+R10 -> 185.19465 | S12: =R12*(1-Assumptions!C27)+S10 -> 233.60539 | T12: =S12*(1-Assumptions!C27)+T10 -> 285.9236 | U12: =T12*(1-Assumptions!C27)+U10 -> 342.39969 | V12: =U12*(1-Assumptions!C27)+V10 -> 403.40073 | W12: =V12*(1-Assumptions!C27)+W10 -> 469.42398 | X12: =W12*(1-Assumptions!C27)+X10 -> 541.11357 | Y12: =X12*(1-Assumptions!C27)+Y10 -> 619.28103 | Z12: =Y12*(1-Assumptions!C27)+Z10 -> 704.89409 | AA12: =Z12*(1-Assumptions!C27)+AA10 -> 800.6459 | AB12: =AA12*(1-Assumptions!C27)+AB10 -> 907.9801 | AC12: =AB12*(1-Assumptions!C27)+AC10 -> 1028.6549 | AD12: =AC12*(1-Assumptions!C27)+AD10 -> 1164.7949 | AE12: =AD12*(1-Assumptions!C27)+AE10 -> 1318.9525 | AF12: =AE12*(1-Assumptions!C27)+AF10 -> 1494.181 | AG12: =AF12*(1-Assumptions!C27)+AG10 -> 1694.1208 | AH12: =AG12*(1-Assumptions!C27)+AH10 -> 1923.1016 | AI12: =AH12*(1-Assumptions!C27)+AI10 -> 2186.2634 | AJ12: =AI12*(1-Assumptions!C27)+AJ10 -> 2489.6989 | AK12: =AJ12*(1-Assumptions!C27)+AK10 -> 2840.6231 | AL12: =M12 -> 0 | AM12: =Y12 -> 619.28103 | AN12: =AK12 -> 2840.6231 | AO12: Premium users MOVE from basic — no double-counting.
A13: B2B contracts signed (cumulative) | B13: =0 -> 0 | C13: =0 -> 0 | D13: =0 -> 0 | E13: =0 -> 0 | F13: =0 -> 0 | G13: =Assumptions!C29 -> 1.5 | H13: =G13+Assumptions!C29 -> 3 | I13: =H13+Assumptions!C29 -> 4.5 | J13: =I13+Assumptions!C29 -> 6 | K13: =J13+Assumptions!C29 -> 7.5 | L13: =K13+Assumptions!C29 -> 9 | M13: =L13+Assumptions!C29 -> 10.5 | N13: =M13+Assumptions!C30 -> 13.5 | O13: =N13+Assumptions!C30 -> 16.5 | P13: =O13+Assumptions!C30 -> 19.5 | Q13: =P13+Assumptions!C30 -> 22.5 | R13: =Q13+Assumptions!C30 -> 25.5 | S13: =R13+Assumptions!C30 -> 28.5 | T13: =S13+Assumptions!C30 -> 31.5 | U13: =T13+Assumptions!C30 -> 34.5 | V13: =U13+Assumptions!C30 -> 37.5 | W13: =V13+Assumptions!C30 -> 40.5 | X13: =W13+Assumptions!C30 -> 43.5 | Y13: =X13+Assumptions!C30 -> 46.5 | Z13: =Y13+Assumptions!C31 -> 50 | AA13: =Z13+Assumptions!C31 -> 53.5 | AB13: =AA13+Assumptions!C31 -> 57 | AC13: =AB13+Assumptions!C31 -> 60.5 | AD13: =AC13+Assumptions!C31 -> 64 | AE13: =AD13+Assumptions!C31 -> 67.5 | AF13: =AE13+Assumptions!C31 -> 71 | AG13: =AF13+Assumptions!C31 -> 74.5 | AH13: =AG13+Assumptions!C31 -> 78 | AI13: =AH13+Assumptions!C31 -> 81.5 | AJ13: =AI13+Assumptions!C31 -> 85 | AK13: =AJ13+Assumptions!C31 -> 88.5 | AL13: =M13 -> 10.5 | AM13: =Y13 -> 46.5 | AN13: =AK13 -> 88.5
A14: B2B employees active (EoM) | B14: =0 -> 0 | C14: =0 -> 0 | D14: =0 -> 0 | E14: =0 -> 0 | F14: =0 -> 0 | G14: =Assumptions!C29*Assumptions!C32 -> 180 | H14: =G14*(1-(1-(1-Assumptions!C33)^(1/12)))+Assumptions!C29*Assumptions!C32 -> 356.68378 | I14: =H14*(1-(1-(1-Assumptions!C33)^(1/12)))+Assumptions!C29*Assumptions!C32 -> 530.11242 | J14: =I14*(1-(1-(1-Assumptions!C33)^(1/12)))+Assumptions!C29*Assumptions!C32 -> 700.34591 | K14: =J14*(1-(1-(1-Assumptions!C33)^(1/12)))+Assumptions!C29*Assumptions!C32 -> 867.44311 | L14: =K14*(1-(1-(1-Assumptions!C33)^(1/12)))+Assumptions!C29*Assumptions!C32 -> 1031.4618 | M14: =L14*(1-(1-(1-Assumptions!C33)^(1/12)))+Assumptions!C29*Assumptions!C32 -> 1192.4587 | N14: =M14*(1-(1-(1-Assumptions!C33)^(1/12)))+Assumptions!C30*Assumptions!C32 -> 1530.4895 | O14: =N14*(1-(1-(1-Assumptions!C33)^(1/12)))+Assumptions!C30*Assumptions!C32 -> 1862.2925 | P14: =O14*(1-(1-(1-Assumptions!C33)^(1/12)))+Assumptions!C30*Assumptions!C32 -> 2187.9826 | Q14: =P14*(1-(1-(1-Assumptions!C33)^(1/12)))+Assumptions!C30*Assumptions!C32 -> 2507.6724 | R14: =Q14*(1-(1-(1-Assumptions!C33)^(1/12)))+Assumptions!C30*Assumptions!C32 -> 2821.4724 | S14: =R14*(1-(1-(1-Assumptions!C33)^(1/12)))+Assumptions!C30*Assumptions!C32 -> 3129.4911 | T14: =S14*(1-(1-(1-Assumptions!C33)^(1/12)))+Assumptions!C30*Assumptions!C32 -> 3431.835 | U14: =T14*(1-(1-(1-Assumptions!C33)^(1/12)))+Assumptions!C30*Assumptions!C32 -> 3728.6087 | V14: =U14*(1-(1-(1-Assumptions!C33)^(1/12)))+Assumptions!C30*Assumptions!C32 -> 4019.9148 | W14: =V14*(1-(1-(1-Assumptions!C33)^(1/12)))+Assumptions!C30*Assumptions!C32 -> 4305.854 | X14: =W14*(1-(1-(1-Assumptions!C33)^(1/12)))+Assumptions!C30*Assumptions!C32 -> 4586.5252 | Y14: =X14*(1-(1-(1-Assumptions!C33)^(1/12)))+Assumptions!C30*Assumptions!C32 -> 4862.0255 | Z14: =Y14*(1-(1-(1-Assumptions!C33)^(1/12)))+Assumptions!C31*Assumptions!C32 -> 5192.4501 | AA14: =Z14*(1-(1-(1-Assumptions!C33)^(1/12)))+Assumptions!C31*Assumptions!C32 -> 5516.7872 | AB14: =AA14*(1-(1-(1-Assumptions!C33)^(1/12)))+Assumptions!C31*Assumptions!C32 -> 5835.1488 | AC14: =AB14*(1-(1-(1-Assumptions!C33)^(1/12)))+Assumptions!C31*Assumptions!C32 -> 6147.6451 | AD14: =AC14*(1-(1-(1-Assumptions!C33)^(1/12)))+Assumptions!C31*Assumptions!C32 -> 6454.3842 | AE14: =AD14*(1-(1-(1-Assumptions!C33)^(1/12)))+Assumptions!C31*Assumptions!C32 -> 6755.472 | AF14: =AE14*(1-(1-(1-Assumptions!C33)^(1/12)))+Assumptions!C31*Assumptions!C32 -> 7051.0128 | AG14: =AF14*(1-(1-(1-Assumptions!C33)^(1/12)))+Assumptions!C31*Assumptions!C32 -> 7341.1087 | AH14: =AG14*(1-(1-(1-Assumptions!C33)^(1/12)))+Assumptions!C31*Assumptions!C32 -> 7625.86 | AI14: =AH14*(1-(1-(1-Assumptions!C33)^(1/12)))+Assumptions!C31*Assumptions!C32 -> 7905.3652 | AJ14: =AI14*(1-(1-(1-Assumptions!C33)^(1/12)))+Assumptions!C31*Assumptions!C32 -> 8179.7209 | AK14: =AJ14*(1-(1-(1-Assumptions!C33)^(1/12)))+Assumptions!C31*Assumptions!C32 -> 8449.0221 | AL14: =M14 -> 1192.4587 | AM14: =Y14 -> 4862.0255 | AN14: =AK14 -> 8449.0221 | AO14: Prior × (1-monthly logo churn) + new seats.
A15: TOTAL PAYING USERS (EoM) | B15: =B11+B12+B14 -> 38.4 | C15: =C11+C12+C14 -> 80.256 | D15: =D11+D12+D14 -> 126.50112 | E15: =E11+E12+E14 -> 628.25968 | F15: =F11+F12+F14 -> 1096.6743 | G15: =G11+G12+G14 -> 1717.1559 | H15: =H11+H12+H14 -> 2311.6488 | I15: =I11+I12+I14 -> 2885.4116 | ... AK15: =AK11+AK12+AK14 -> 80699.471 | AL15: =M15 -> 5081.4564 | AM15: =Y15 -> 20199.213 | AN15: =AK15 -> 80699.471 | AO15: Basic + premium + B2B. Premium NOT double-counted.
A17: SECTION 2 — REVENUE
A18: B2C basic subscriptions | B18: =B11*Assumptions!C4 -> 191.616 | C18: =(B11+C11)/2*Assumptions!C4 -> 296.04672 | D18: =(C11+D11)/2*Assumptions!C4 -> 515.85901 | E18: =(D11+E11)/2*Assumptions!C4 -> 1883.1282 | F18: =(E11+F11)/2*Assumptions!C4 -> 4303.7102 | G18: =(F11+G11)/2*Assumptions!C4 -> 6571.4064 | H18: =(G11+H11)/2*Assumptions!C4 -> 8712.8417 | I18: =(H11+I11)/2*Assumptions!C4 -> 10754.109 | J18: =(I11+J11)/2*Assumptions!C4 -> 12721.219 | K18: =(J11+K11)/2*Assumptions!C4 -> 14640.575 | L18: =(K11+L11)/2*Assumptions!C4 -> 16539.481 | M18: =(L11+M11)/2*Assumptions!C4 -> 18446.704 | N18: =(M11+N11)/2*Assumptions!C4 -> 21161.472 | O18: =(N11+O11)/2*Assumptions!C4 -> 24654.747 | P18: =(O11+P11)/2*Assumptions!C4 -> 28138.415 | Q18: =(P11+Q11)/2*Assumptions!C4 -> 31665.108 | R18: =(Q11+R11)/2*Assumptions!C4 -> 35291.979 | S18: =(R11+S11)/2*Assumptions!C4 -> 39081.995 | T18: =(S11+T11)/2*Assumptions!C4 -> 43105.437 | U18: =(T11+U11)/2*Assumptions!C4 -> 47441.616 | V18: =(U11+V11)/2*Assumptions!C4 -> 52180.863 | W18: =(V11+W11)/2*Assumptions!C4 -> 57426.858 | X18: =(W11+X11)/2*Assumptions!C4 -> 63299.333 | Y18: =(X11+Y11)/2*Assumptions!C4 -> 69925.302 | Z18: =(Y11+Z11)/2*Assumptions!C4 -> 77954.404 | AA18: =(Z11+AA11)/2*Assumptions!C4 -> 87593.666 | AB18: =(AA11+AB11)/2*Assumptions!C4 -> 98587.108 | AC18: =(AB11+AC11)/2*Assumptions!C4 -> 111203.87 | AD18: =(AC11+AD11)/2*Assumptions!C4 -> 125759.84 | AE18: =(AD11+AE11)/2*Assumptions!C4 -> 142626.19 | AF18: =(AE11+AF11)/2*Assumptions!C4 -> 162239.43 | AG18: =(AF11+AG11)/2*Assumptions!C4 -> 185113.27 | AH18: =(AG11+AH11)/2*Assumptions!C4 -> 211852.6 | AI18: =(AH11+AI11)/2*Assumptions!C4 -> 243169.98 | AJ18: =(AI11+AJ11)/2*Assumptions!C4 -> 279905.13 | AK18: =(AJ11+AK11)/2*Assumptions!C4 -> 323047.88 | AL18: =SUM(B18:M18) -> 95576.696 | AM18: =SUM(N18:Y18) -> 513373.13 | AN18: =SUM(Z18:AK18) -> 2049053.4
A19: B2C premium subscriptions (from M13) | B19: =0 -> 0 | C19: =0 -> 0 | D19: =0 -> 0 | E19: =0 -> 0 | F19: =0 -> 0 | G19: =0 -> 0 | H19: =0 -> 0 | I19: =0 -> 0 | ... M19: =0 -> 0 | N19: =N12*Assumptions!C5 -> 378.8856 | O19: =(N12+O12)/2*Assumptions!C5 -> 595.02269 | P19: =(O12+P12)/2*Assumptions!C5 -> 1052.5823 | Q19: =(P12+Q12)/2*Assumptions!C5 -> 1559.8547 | R19: =(Q12+R12)/2*Assumptions!C5 -> 2115.6916 | S19: =(R12+S12)/2*Assumptions!C5 -> 2720.1063 | T19: =(S12+T12)/2*Assumptions!C5 -> 3374.3408 | U19: =(T12+U12)/2*Assumptions!C5 -> 4080.9598 | V19: =(U12+V12)/2*Assumptions!C5 -> 4843.9737 | W19: =(V12+W12)/2*Assumptions!C5 -> 5668.9965 | X19: =(W12+X12)/2*Assumptions!C5 -> 6563.4414 | Y19: =(X12+Y12)/2*Assumptions!C5 -> 7536.7629 | Z19: =(Y12+Z12)/2*Assumptions!C5 -> 8600.5174 | AA19: =(Z12+AA12)/2*Assumptions!C5 -> 9778.4822 | AB19: =(AA12+AB12)/2*Assumptions!C5 -> 11097.526 | AC19: =(AB12+AC12)/2*Assumptions!C5 -> 12578.444 | AD19: =(AC12+AD12)/2*Assumptions!C5 -> 14246.456 | AE19: =(AD12+AE12)/2*Assumptions!C5 -> 16131.939 | AF19: =(AE12+AF12)/2*Assumptions!C5 -> 18271.302 | AG19: =(AF12+AG12)/2*Assumptions!C5 -> 20708.02 | AH19: =(AG12+AH12)/2*Assumptions!C5 -> 23493.86 | AI19: =(AH12+AI12)/2*Assumptions!C5 -> 26690.326 | AJ19: =(AI12+AJ12)/2*Assumptions!C5 -> 30370.375 | AK19: =(AJ12+AK12)/2*Assumptions!C5 -> 34620.441 | AL19: =SUM(B19:M19) -> 0 | AM19: =SUM(N19:Y19) -> 40490.618 | AN19: =SUM(Z19:AK19) -> 226587.69
A20: B2B corporate wellbeing | B20: =0 -> 0 | C20: =0 -> 0 | D20: =0 -> 0 | E20: =0 -> 0 | F20: =0 -> 0 | G20: =G14*Assumptions!C6 -> 718.2 | H20: =H14*Assumptions!C6 -> 1423.1683 | I20: =I14*Assumptions!C6 -> 2115.1486 | J20: =J14*Assumptions!C6 -> 2794.3802 | K20: =K14*Assumptions!C6 -> 3461.098 | L20: =L14*Assumptions!C6 -> 4115.5326 | M20: =M14*Assumptions!C6 -> 4757.9102 | N20: =N14*Assumptions!C7 -> 9167.6319 | O20: =O14*Assumptions!C7 -> 11155.132 | P20: =P14*Assumptions!C7 -> 13106.016 | Q20: =Q14*Assumptions!C7 -> 15020.958 | R20: =R14*Assumptions!C7 -> 16900.62 | S20: =S14*Assumptions!C7 -> 18745.652 | T20: =T14*Assumptions!C7 -> 20556.692 | U20: =U14*Assumptions!C7 -> 22334.366 | V20: =V14*Assumptions!C7 -> 24079.289 | W20: =W14*Assumptions!C7 -> 25792.065 | X20: =X14*Assumptions!C7 -> 27473.286 | Y20: =Y14*Assumptions!C7 -> 29123.533 | Z20: =Z14*Assumptions!C7 -> 31102.776 | AA20: =AA14*Assumptions!C7 -> 33045.555 | AB20: =AB14*Assumptions!C7 -> 34952.541 | AC20: =AC14*Assumptions!C7 -> 36824.394 | AD20: =AD14*Assumptions!C7 -> 38661.761 | AE20: =AE14*Assumptions!C7 -> 40465.277 | AF20: =AF14*Assumptions!C7 -> 42235.567 | AG20: =AG14*Assumptions!C7 -> 43973.241 | AH20: =AH14*Assumptions!C7 -> 45678.901 | AI20: =AI14*Assumptions!C7 -> 47353.137 | AJ20: =AJ14*Assumptions!C7 -> 48996.528 | AK20: =AK14*Assumptions!C7 -> 50609.642 | AL20: =SUM(B20:M20) -> 19385.438 | AM20: =SUM(N20:Y20) -> 233455.24 | AN20: =SUM(Z20:AK20) -> 493899.32
A21: Events & workshops (net) | B21: =0 -> 0 | C21: =0 -> 0 | D21: =Assumptions!C35 -> 500 | E21: =Assumptions!C35 -> 500 | F21: =Assumptions!C35 -> 500 | G21: =Assumptions!C35 -> 500 | H21: =Assumptions!C35 -> 500 | I21: =Assumptions!C35 -> 500 | J21: =Assumptions!C35 -> 500 | K21: =Assumptions!C35 -> 500 | L21: =Assumptions!C35 -> 500 | M21: =Assumptions!C35 -> 500 | N21: =Assumptions!C36 -> 1000 | O21: =Assumptions!C36 -> 1000 | P21: =Assumptions!C36 -> 1000 | Q21: =Assumptions!C36 -> 1000 | R21: =Assumptions!C36 -> 1000 | S21: =Assumptions!C36 -> 1000 | T21: =Assumptions!C36 -> 1000 | U21: =Assumptions!C36 -> 1000 | V21: =Assumptions!C36 -> 1000 | W21: =Assumptions!C36 -> 1000 | X21: =Assumptions!C36 -> 1000 | Y21: =Assumptions!C36 -> 1000 | Z21: =Assumptions!C37 -> 1500 | AA21: =Assumptions!C37 -> 1500 | AB21: =Assumptions!C37 -> 1500 | AC21: =Assumptions!C37 -> 1500 | AD21: =Assumptions!C37 -> 1500 | AE21: =Assumptions!C37 -> 1500 | AF21: =Assumptions!C37 -> 1500 | AG21: =Assumptions!C37 -> 1500 | AH21: =Assumptions!C37 -> 1500 | AI21: =Assumptions!C37 -> 1500 | AJ21: =Assumptions!C37 -> 1500 | AK21: =Assumptions!C37 -> 1500 | AL21: =SUM(B21:M21) -> 5000 | AM21: =SUM(N21:Y21) -> 12000 | AN21: =SUM(Z21:AK21) -> 18000 | AO21: €420 earned to date → €500 conservative. NOT in MRR.
A22: Clinical B2B referral fees (€/contract/mo, from M6) | B22: =0 -> 0 | C22: =0 -> 0 | D22: =0 -> 0 | E22: =0 -> 0 | F22: =0 -> 0 | G22: =G13*Assumptions!C39 -> 450 | H22: =H13*Assumptions!C39 -> 900 | I22: =I13*Assumptions!C39 -> 1350 | J22: =J13*Assumptions!C39 -> 1800 | K22: =K13*Assumptions!C39 -> 2250 | L22: =L13*Assumptions!C39 -> 2700 | M22: =M13*Assumptions!C39 -> 3150 | N22: =N13*Assumptions!C39 -> 4050 | O22: =O13*Assumptions!C39 -> 4950 | P22: =P13*Assumptions!C39 -> 5850 | Q22: =Q13*Assumptions!C39 -> 6750 | R22: =R13*Assumptions!C39 -> 7650 | S22: =S13*Assumptions!C39 -> 8550 | T22: =T13*Assumptions!C39 -> 9450 | U22: =U13*Assumptions!C39 -> 10350 | V22: =V13*Assumptions!C39 -> 11250 | W22: =W13*Assumptions!C39 -> 12150 | X22: =X13*Assumptions!C39 -> 13050 | Y22: =Y13*Assumptions!C39 -> 13950 | Z22: =Z13*Assumptions!C39 -> 15000 | AA22: =AA13*Assumptions!C39 -> 16050 | AB22: =AB13*Assumptions!C39 -> 17100 | AC22: =AC13*Assumptions!C39 -> 18150 | AD22: =AD13*Assumptions!C39 -> 19200 | AE22: =AE13*Assumptions!C39 -> 20250 | AF22: =AF13*Assumptions!C39 -> 21300 | AG22: =AG13*Assumptions!C39 -> 22350 | AH22: =AH13*Assumptions!C39 -> 23400 | AI22: =AI13*Assumptions!C39 -> 24450 | AJ22: =AJ13*Assumptions!C39 -> 25500 | AK22: =AK13*Assumptions!C39 -> 26550 | AL22: =SUM(B22:M22) -> 12600 | AM22: =SUM(N22:Y22) -> 108000 | AN22: =SUM(Z22:AK22) -> 249300
A23: Brand partnerships (0 in conservative; upside only) | B23: =0 -> 0 | C23: =0 -> 0 | D23: =0 -> 0 | E23: =0 -> 0 | F23: =0 -> 0 | G23: =0 -> 0 | H23: =0 -> 0 | I23: =0 -> 0 | ... Y23: =0 -> 0 | Z23: =Assumptions!C38 -> 0 | AA23: =Assumptions!C38 -> 0 | AB23: =Assumptions!C38 -> 0 | AC23: =Assumptions!C38 -> 0 | AD23: =Assumptions!C38 -> 0 | AE23: =Assumptions!C38 -> 0 | AF23: =Assumptions!C38 -> 0 | AG23: =Assumptions!C38 -> 0 | AH23: =Assumptions!C38 -> 0 | AI23: =Assumptions!C38 -> 0 | AJ23: =Assumptions!C38 -> 0 | AK23: =Assumptions!C38 -> 0 | AL23: =SUM(B23:M23) -> 0 | AM23: =SUM(N23:Y23) -> 0 | AN23: =SUM(Z23:AK23) -> 0
A24: TOTAL REVENUE | B24: =B18+B19+B20+B21+B22+B23 -> 191.616 | C24: =C18+C19+C20+C21+C22+C23 -> 296.04672 | D24: =D18+D19+D20+D21+D22+D23 -> 1015.859 | E24: =E18+E19+E20+E21+E22+E23 -> 2383.1282 | F24: =F18+F19+F20+F21+F22+F23 -> 4803.7102 | G24: =G18+G19+G20+G21+G22+G23 -> 8239.6064 | H24: =H18+H19+H20+H21+H22+H23 -> 11536.01 | I24: =I18+I19+I20+I21+I22+I23 -> 14719.258 | ... AK24: =AK18+AK19+AK20+AK21+AK22+AK23 -> 436327.96 | AL24: =SUM(B24:M24) -> 132562.13 | AM24: =SUM(N24:Y24) -> 907318.98 | AN24: =SUM(Z24:AK24) -> 3036840.4
A25: MRR — recurring only (basic + premium + B2B) | B25: =B18+B19+B20 -> 191.616 | C25: =C18+C19+C20 -> 296.04672 | D25: =D18+D19+D20 -> 515.85901 | E25: =E18+E19+E20 -> 1883.1282 | F25: =F18+F19+F20 -> 4303.7102 | G25: =G18+G19+G20 -> 7289.6064 | H25: =H18+H19+H20 -> 10136.01 | I25: =I18+I19+I20 -> 12869.258 | ... AK25: =AK18+AK19+AK20 -> 408277.96 | AL25: =M25 -> 23204.614 | AM25: =Y25 -> 106585.6 | AN25: =AK25 -> 408277.96 | AO25: Events and clinical fees excluded — VCs strip them.
A26: ARR (MRR × 12) | B26: =B25*12 -> 2299.392 | C26: =C25*12 -> 3552.5606 | D26: =D25*12 -> 6190.3082 | E26: =E25*12 -> 22597.538 | F26: =F25*12 -> 51644.522 | G26: =G25*12 -> 87475.276 | H26: =H25*12 -> 121632.12 | I26: =I25*12 -> 154431.09 | ... AK26: =AK25*12 -> 4899335.5 | AL26: =M26 -> 278455.37 | AM26: =Y26 -> 1279027.2 | AN26: =AK26 -> 4899335.5
A28: SECTION 3 — COSTS
A29: [helper] Trailing-12-month B2C gross revenue (fee-tier test) | B29: =SUM(B18:B18)+SUM(B19:B19) -> 191.616 | C29: =SUM(B18:C18)+SUM(B19:C19) -> 487.66272 | D29: =SUM(B18:D18)+SUM(B19:D19) -> 1003.5217 | E29: =SUM(B18:E18)+SUM(B19:E19) -> 2886.6499 | F29: =SUM(B18:F18)+SUM(B19:F19) -> 7190.3601 | G29: =SUM(B18:G18)+SUM(B19:G19) -> 13761.766 | H29: =SUM(B18:H18)+SUM(B19:H19) -> 22474.608 | I29: =SUM(B18:I18)+SUM(B19:I19) -> 33228.717 | J29: =SUM(B18:J18)+SUM(B19:J19) -> 45949.936 | K29: =SUM(B18:K18)+SUM(B19:K19) -> 60590.511 | L29: =SUM(B18:L18)+SUM(B19:L19) -> 77129.992 | M29: =SUM(B18:M18)+SUM(B19:M19) -> 95576.696 | N29: =SUM(C18:N18)+SUM(C19:N19) -> 116925.44 | O29: =SUM(D18:O18)+SUM(D19:O19) -> 141879.16 | P29: =SUM(E18:P18)+SUM(E19:P19) -> 170554.3 | Q29: =SUM(F18:Q18)+SUM(F19:Q19) -> 201896.13 | R29: =SUM(G18:R18)+SUM(G19:R19) -> 235000.09 | S29: =SUM(H18:S18)+SUM(H19:S19) -> 270230.79 | T29: =SUM(I18:T18)+SUM(I19:T19) -> 307997.72 | ... AK29: =SUM(Z18:AK18)+SUM(Z19:AK19) -> 2275641
A30: App store fees — CORRECTED (15% under $1M; 30% above) | B30: =IF(B29<Assumptions!C43,(B18+B19)*Assumptions!C41,(B18+B19)*Assumptions!C42) -> 28.7424 | C30: =IF(C29<Assumptions!C43,(C18+C19)*Assumptions!C41,(C18+C19)*Assumptions!C42) -> 44.407008 | D30: =IF(D29<Assumptions!C43,(D18+D19)*Assumptions!C41,(D18+D19)*Assumptions!C42) -> 77.378852 | E30: =IF(E29<Assumptions!C43,(E18+E19)*Assumptions!C41,(E18+E19)*Assumptions!C42) -> 282.46923 | F30: =IF(F29<Assumptions!C43,(F18+F19)*Assumptions!C41,(F18+F19)*Assumptions!C42) -> 645.55653 | G30: =IF(G29<Assumptions!C43,(G18+G19)*Assumptions!C41,(G18+G19)*Assumptions!C42) -> 985.71095 | H30: =IF(H29<Assumptions!C43,(H18+H19)*Assumptions!C41,(H18+H19)*Assumptions!C42) -> 1306.9263 | I30: =IF(I29<Assumptions!C43,(I18+I19)*Assumptions!C41,(I18+I19)*Assumptions!C42) -> 1613.1163 | J30: =IF(J29<Assumptions!C43,(J18+J19)*Assumptions!C41,(J18+J19)*Assumptions!C42) -> 1908.1828 | K30: =IF(K29<Assumptions!C43,(K18+K19)*Assumptions!C41,(K18+K19)*Assumptions!C42) -> 2196.0862 | L30: =IF(L29<Assumptions!C43,(L18+L19)*Assumptions!C41,(L18+L19)*Assumptions!C42) -> 2480.9222 | M30: =IF(M29<Assumptions!C43,(M18+M19)*Assumptions!C41,(M18+M19)*Assumptions!C42) -> 2767.0056 | N30: =IF(N29<Assumptions!C43,(N18+N19)*Assumptions!C41,(N18+N19)*Assumptions!C42) -> 3231.0537 | O30: =IF(O29<Assumptions!C43,(O18+O19)*Assumptions!C41,(O18+O19)*Assumptions!C42) -> 3787.4654 | P30: =IF(P29<Assumptions!C43,(P18+P19)*Assumptions!C41,(P18+P19)*Assumptions!C42) -> 4378.6495 | Q30: =IF(Q29<Assumptions!C43,(Q18+Q19)*Assumptions!C41,(Q18+Q19)*Assumptions!C42) -> 4983.7445 | R30: =IF(R29<Assumptions!C43,(R18+R19)*Assumptions!C41,(R18+R19)*Assumptions!C42) -> 5611.1505 | S30: =IF(S29<Assumptions!C43,(S18+S19)*Assumptions!C41,(S18+S19)*Assumptions!C42) -> 6270.3152 | T30: =IF(T29<Assumptions!C43,(T18+T19)*Assumptions!C41,(T18+T19)*Assumptions!C42) -> 6971.9667 | U30: =IF(U29<Assumptions!C43,(U18+U19)*Assumptions!C41,(U18+U19)*Assumptions!C42) -> 7728.3863 | V30: =IF(V29<Assumptions!C43,(V18+V19)*Assumptions!C41,(V18+V19)*Assumptions!C42) -> 8553.7255 | W30: =IF(W29<Assumptions!C43,(W18+W19)*Assumptions!C41,(W18+W19)*Assumptions!C42) -> 9464.3781 | X30: =IF(X29<Assumptions!C43,(X18+X19)*Assumptions!C41,(X18+X19)*Assumptions!C42) -> 10479.416 | Y30: =IF(Y29<Assumptions!C43,(Y18+Y19)*Assumptions!C41,(Y18+Y19)*Assumptions!C42) -> 11619.31 | Z30: =IF(Z29<Assumptions!C43,(Z18+Z19)*Assumptions!C41,(Z18+Z19)*Assumptions!C42) -> 12983.238 | AA30: =IF(AA29<Assumptions!C43,(AA18+AA19)*Assumptions!C41,(AA18+AA19)*Assumptions!C42) -> 14605.822 | AB30: =IF(AB29<Assumptions!C43,(AB18+AB19)*Assumptions!C41,(AB18+AB19)*Assumptions!C42) -> 16452.695 | AC30: =IF(AC29<Assumptions!C43,(AC18+AC19)*Assumptions!C41,(AC18+AC19)*Assumptions!C42) -> 18567.347 | AD30: =IF(AD29<Assumptions!C43,(AD18+AD19)*Assumptions!C41,(AD18+AD19)*Assumptions!C42) -> 42001.888 | AE30: =IF(AE29<Assumptions!C43,(AE18+AE19)*Assumptions!C41,(AE18+AE19)*Assumptions!C42) -> 47627.438 | AF30: =IF(AF29<Assumptions!C43,(AF18+AF19)*Assumptions!C41,(AF18+AF19)*Assumptions!C42) -> 54153.22 | AG30: =IF(AG29<Assumptions!C43,(AG18+AG19)*Assumptions!C41,(AG18+AG19)*Assumptions!C42) -> 61746.387 | AH30: =IF(AH29<Assumptions!C43,(AH18+AH19)*Assumptions!C41,(AH18+AH19)*Assumptions!C42) -> 70603.937 | AI30: =IF(AI29<Assumptions!C43,(AI18+AI19)*Assumptions!C41,(AI18+AI19)*Assumptions!C42) -> 80958.092 | AJ30: =IF(AJ29<Assumptions!C43,(AJ18+AJ19)*Assumptions!C41,(AJ18+AJ19)*Assumptions!C42) -> 93082.652 | AK30: =IF(AK29<Assumptions!C43,(AK18+AK19)*Assumptions!C41,(AK18+AK19)*Assumptions!C42) -> 107300.5 | AL30: =SUM(B30:M30) -> 14336.504 | AM30: =SUM(N30:Y30) -> 83079.562 | AN30: =SUM(Z30:AK30) -> 620083.21 | AO30: CORRECTED: 15% until trailing-12mo B2C > ~$1M; 30% after. Original was backwards.
A31: Payment processing (Stripe 1.4% on B2B) | B31: =B20*Assumptions!C44 -> 0 | C31: =C20*Assumptions!C44 -> 0 | D31: =D20*Assumptions!C44 -> 0 | E31: =E20*Assumptions!C44 -> 0 | F31: =F20*Assumptions!C44 -> 0 | G31: =G20*Assumptions!C44 -> 10.0548 | H31: =H20*Assumptions!C44 -> 19.924356 | I31: =I20*Assumptions!C44 -> 29.61208 | J31: =J20*Assumptions!C44 -> 39.121323 | K31: =K20*Assumptions!C44 -> 48.455372 | L31: =L20*Assumptions!C44 -> 57.617456 | M31: =M20*Assumptions!C44 -> 66.610743 | N31: =N20*Assumptions!C44 -> 128.34685 | O31: =O20*Assumptions!C44 -> 156.17185 | P31: =P20*Assumptions!C44 -> 183.48422 | Q31: =Q20*Assumptions!C44 -> 210.29341 | R31: =R20*Assumptions!C44 -> 236.60867 | S31: =S20*Assumptions!C44 -> 262.43912 | T31: =T20*Assumptions!C44 -> 287.79368 | U31: =U20*Assumptions!C44 -> 312.68112 | V31: =V20*Assumptions!C44 -> 337.11005 | W31: =W20*Assumptions!C44 -> 361.08892 | X31: =X20*Assumptions!C44 -> 384.626 | Y31: =Y20*Assumptions!C44 -> 407.72946 | Z31: =Z20*Assumptions!C44 -> 435.43887 | AA31: =AA20*Assumptions!C44 -> 462.63777 | AB31: =AB20*Assumptions!C44 -> 489.33558 | AC31: =AC20*Assumptions!C44 -> 515.54152 | AD31: =AD20*Assumptions!C44 -> 541.26466 | AE31: =AE20*Assumptions!C44 -> 566.51388 | AF31: =AF20*Assumptions!C44 -> 591.29793 | AG31: =AG20*Assumptions!C44 -> 615.62537 | AH31: =AH20*Assumptions!C44 -> 639.50462 | AI31: =AI20*Assumptions!C44 -> 662.94392 | AJ31: =AJ20*Assumptions!C44 -> 685.95139 | AK31: =AK20*Assumptions!C44 -> 708.53499 | AL31: =SUM(B31:M31) -> 271.39613 | AM31: =SUM(N31:Y31) -> 3268.3734 | AN31: =SUM(Z31:AK31) -> 6914.5905
A32: AI API costs (from M6, scales with users, capped) | B32: =0 -> 0 | C32: =0 -> 0 | D32: =0 -> 0 | E32: =0 -> 0 | F32: =0 -> 0 | G32: =MIN(Assumptions!C48,Assumptions!C46+(G15/500)*Assumptions!C47) -> 571.71559 | H32: =MIN(Assumptions!C48,Assumptions!C46+(H15/500)*Assumptions!C47) -> 631.16488 | I32: =MIN(Assumptions!C48,Assumptions!C46+(I15/500)*Assumptions!C47) -> 688.54116 | J32: =MIN(Assumptions!C48,Assumptions!C46+(J15/500)*Assumptions!C47) -> 744.37317 | K32: =MIN(Assumptions!C48,Assumptions!C46+(K15/500)*Assumptions!C47) -> 799.20231 | L32: =MIN(Assumptions!C48,Assumptions!C46+(L15/500)*Assumptions!C47) -> 853.59325 | M32: =MIN(Assumptions!C48,Assumptions!C46+(M15/500)*Assumptions!C47) -> 908.14564 | N32: =MIN(Assumptions!C48,Assumptions!C46+(N15/500)*Assumptions!C47) -> 1015.2211 | O32: =MIN(Assumptions!C48,Assumptions!C46+(O15/500)*Assumptions!C47) -> 1121.3845 | P32: =MIN(Assumptions!C48,Assumptions!C46+(P15/500)*Assumptions!C47) -> 1227.6412 | Q32: =MIN(Assumptions!C48,Assumptions!C46+(Q15/500)*Assumptions!C47) -> 1335.0832 | R32: =MIN(Assumptions!C48,Assumptions!C46+(R15/500)*Assumptions!C47) -> 1444.9136 | S32: =MIN(Assumptions!C48,Assumptions!C46+(S15/500)*Assumptions!C47) -> 1558.4753 | T32: =MIN(Assumptions!C48,Assumptions!C46+(T15/500)*Assumptions!C47) -> 1677.283 | U32: =MIN(Assumptions!C48,Assumptions!C46+(U15/500)*Assumptions!C47) -> 1803.0612 | V32: =MIN(Assumptions!C48,Assumptions!C46+(V15/500)*Assumptions!C47) -> 1937.7885 | W32: =MIN(Assumptions!C48,Assumptions!C46+(W15/500)*Assumptions!C47) -> 2083.7485 | X32: =MIN(Assumptions!C48,Assumptions!C46+(X15/500)*Assumptions!C47) -> 2243.5906 | Y32: =MIN(Assumptions!C48,Assumptions!C46+(Y15/500)*Assumptions!C47) -> 2419.9213 | Z32: =MIN(Assumptions!C48,Assumptions!C46+(Z15/500)*Assumptions!C47) -> 2642.3688 | AA32: =MIN(Assumptions!C48,Assumptions!C46+(AA15/500)*Assumptions!C47) -> 2889.8771 | AB32: =MIN(Assumptions!C48,Assumptions!C46+(AB15/500)*Assumptions!C47) -> 3167.5662 | AC32: =MIN(Assumptions!C48,Assumptions!C46+(AC15/500)*Assumptions!C47) -> 3481.4456 | AD32: =MIN(Assumptions!C48,Assumptions!C46+(AD15/500)*Assumptions!C47) -> 3500 | AE32: =MIN(Assumptions!C48,Assumptions!C46+(AE15/500)*Assumptions!C47) -> 3500 | AF32: =MIN(Assumptions!C48,Assumptions!C46+(AF15/500)*Assumptions!C47) -> 3500 | AG32: =MIN(Assumptions!C48,Assumptions!C46+(AG15/500)*Assumptions!C47) -> 3500 | AH32: =MIN(Assumptions!C48,Assumptions!C46+(AH15/500)*Assumptions!C47) -> 3500 | AI32: =MIN(Assumptions!C48,Assumptions!C46+(AI15/500)*Assumptions!C47) -> 3500 | AJ32: =MIN(Assumptions!C48,Assumptions!C46+(AJ15/500)*Assumptions!C47) -> 3500 | AK32: =MIN(Assumptions!C48,Assumptions!C46+(AK15/500)*Assumptions!C47) -> 3500 | AL32: =SUM(B32:M32) -> 5196.736 | AM32: =SUM(N32:Y32) -> 19868.112 | AN32: =SUM(Z32:AK32) -> 40181.258
A33: Infrastructure & hosting (base + variable, capped) | B33: =80 -> 80 | C33: =80 -> 80 | D33: =MIN(Assumptions!C71,Assumptions!C69+(D15/400)*Assumptions!C70) -> 647.43792 | E33: =MIN(Assumptions!C71,Assumptions!C69+(E15/400)*Assumptions!C70) -> 835.59738 | F33: =MIN(Assumptions!C71,Assumptions!C69+(F15/400)*Assumptions!C70) -> 1011.2528 | G33: =MIN(Assumptions!C71,Assumptions!C69+(G15/400)*Assumptions!C70) -> 1243.9335 | H33: =MIN(Assumptions!C71,Assumptions!C69+(H15/400)*Assumptions!C70) -> 1466.8683 | I33: =MIN(Assumptions!C71,Assumptions!C69+(I15/400)*Assumptions!C70) -> 1682.0293 | J33: =MIN(Assumptions!C71,Assumptions!C69+(J15/400)*Assumptions!C70) -> 1891.3994 | K33: =MIN(Assumptions!C71,Assumptions!C69+(K15/400)*Assumptions!C70) -> 2097.0087 | L33: =MIN(Assumptions!C71,Assumptions!C69+(L15/400)*Assumptions!C70) -> 2300.9747 | M33: =MIN(Assumptions!C71,Assumptions!C69+(M15/400)*Assumptions!C70) -> 2505.5461 | N33: =MIN(Assumptions!C71,Assumptions!C69+(N15/400)*Assumptions!C70) -> 2907.0792 | O33: =MIN(Assumptions!C71,Assumptions!C69+(O15/400)*Assumptions!C70) -> 3305.192 | P33: =MIN(Assumptions!C71,Assumptions!C69+(P15/400)*Assumptions!C70) -> 3703.6545 | Q33: =MIN(Assumptions!C71,Assumptions!C69+(Q15/400)*Assumptions!C70) -> 4106.5619 | R33: =MIN(Assumptions!C71,Assumptions!C69+(R15/400)*Assumptions!C70) -> 4518.4261 | S33: =MIN(Assumptions!C71,Assumptions!C69+(S15/400)*Assumptions!C70) -> 4944.2825 | T33: =MIN(Assumptions!C71,Assumptions!C69+(T15/400)*Assumptions!C70) -> 5389.8113 | U33: =MIN(Assumptions!C71,Assumptions!C69+(U15/400)*Assumptions!C70) -> 5861.4797 | V33: =MIN(Assumptions!C71,Assumptions!C69+(V15/400)*Assumptions!C70) -> 6366.7069 | W33: =MIN(Assumptions!C71,Assumptions!C69+(W15/400)*Assumptions!C70) -> 6914.0569 | X33: =MIN(Assumptions!C71,Assumptions!C69+(X15/400)*Assumptions!C70) -> 7513.4647 | Y33: =MIN(Assumptions!C71,Assumptions!C69+(Y15/400)*Assumptions!C70) -> 8174.7048 | Z33: =MIN(Assumptions!C71,Assumptions!C69+(Z15/400)*Assumptions!C70) -> 9008.883 | AA33: =MIN(Assumptions!C71,Assumptions!C69+(AA15/400)*Assumptions!C70) -> 9937.0392 | AB33: =MIN(Assumptions!C71,Assumptions!C69+(AB15/400)*Assumptions!C70) -> 10978.373 | AC33: =MIN(Assumptions!C71,Assumptions!C69+(AC15/400)*Assumptions!C70) -> 12155.421 | AD33: =MIN(Assumptions!C71,Assumptions!C69+(AD15/400)*Assumptions!C70) -> 13494.663 | AE33: =MIN(Assumptions!C71,Assumptions!C69+(AE15/400)*Assumptions!C70) -> 15027.24 | AF33: =MIN(Assumptions!C71,Assumptions!C69+(AF15/400)*Assumptions!C70) -> 16789.801 | AG33: =MIN(Assumptions!C71,Assumptions!C69+(AG15/400)*Assumptions!C70) -> 18000 | AH33: =MIN(Assumptions!C71,Assumptions!C69+(AH15/400)*Assumptions!C70) -> 18000 | AI33: =MIN(Assumptions!C71,Assumptions!C69+(AI15/400)*Assumptions!C70) -> 18000 | AJ33: =MIN(Assumptions!C71,Assumptions!C69+(AJ15/400)*Assumptions!C70) -> 18000 | AK33: =MIN(Assumptions!C71,Assumptions!C69+(AK15/400)*Assumptions!C70) -> 18000 | AL33: =SUM(B33:M33) -> 15842.048 | AM33: =SUM(N33:Y33) -> 63705.42 | AN33: =SUM(Z33:AK33) -> 177391.42
A34: Founder stipends ×3 | B34: =Assumptions!C54 -> 900 | C34: =Assumptions!C54 -> 900 | D34: =Assumptions!C54 -> 900 | E34: =Assumptions!C54 -> 900 | F34: =Assumptions!C54 -> 900 | G34: =Assumptions!C54 -> 900 | H34: =Assumptions!C54 -> 900 | I34: =Assumptions!C54 -> 900 | J34: =Assumptions!C54 -> 900 | K34: =Assumptions!C54 -> 900 | L34: =Assumptions!C54 -> 900 | M34: =Assumptions!C54 -> 900 | N34: =Assumptions!C55 -> 9000 | O34: =Assumptions!C55 -> 9000 | P34: =Assumptions!C55 -> 9000 | Q34: =Assumptions!C55 -> 9000 | R34: =Assumptions!C55 -> 9000 | S34: =Assumptions!C55 -> 9000 | T34: =Assumptions!C55 -> 9000 | U34: =Assumptions!C55 -> 9000 | V34: =Assumptions!C55 -> 9000 | W34: =Assumptions!C55 -> 9000 | X34: =Assumptions!C55 -> 9000 | Y34: =Assumptions!C55 -> 9000 | Z34: =Assumptions!C76 -> 12000 | AA34: =Assumptions!C76 -> 12000 | AB34: =Assumptions!C76 -> 12000 | AC34: =Assumptions!C76 -> 12000 | AD34: =Assumptions!C76 -> 12000 | AE34: =Assumptions!C76 -> 12000 | AF34: =Assumptions!C76 -> 12000 | AG34: =Assumptions!C76 -> 12000 | AH34: =Assumptions!C76 -> 12000 | AI34: =Assumptions!C76 -> 12000 | AJ34: =Assumptions!C76 -> 12000 | AK34: =Assumptions!C76 -> 12000 | AL34: =SUM(B34:M34) -> 10800 | AM34: =SUM(N34:Y34) -> 108000 | AN34: =SUM(Z34:AK34) -> 144000
A35: Team salaries & contractors | B35: =0 -> 0 | C35: =0 -> 0 | D35: =Assumptions!C56 -> 5000 | E35: =Assumptions!C56 -> 5000 | F35: =Assumptions!C56 -> 5000 | G35: =Assumptions!C56 -> 5000 | H35: =Assumptions!C57 -> 9000 | I35: =Assumptions!C57 -> 9000 | J35: =Assumptions!C57 -> 9000 | K35: =Assumptions!C57 -> 9000 | L35: =Assumptions!C57 -> 9000 | M35: =Assumptions!C57 -> 9000 | N35: =Assumptions!C58 -> 30000 | O35: =Assumptions!C58 -> 30000 | P35: =Assumptions!C58 -> 30000 | Q35: =Assumptions!C58 -> 30000 | R35: =Assumptions!C58 -> 30000 | S35: =Assumptions!C58 -> 30000 | T35: =Assumptions!C58 -> 30000 | U35: =Assumptions!C58 -> 30000 | V35: =Assumptions!C58 -> 30000 | W35: =Assumptions!C58 -> 30000 | X35: =Assumptions!C58 -> 30000 | Y35: =Assumptions!C58 -> 30000 | Z35: =Assumptions!C59 -> 48000 | AA35: =Assumptions!C59 -> 48000 | AB35: =Assumptions!C59 -> 48000 | AC35: =Assumptions!C59 -> 48000 | AD35: =Assumptions!C59 -> 48000 | AE35: =Assumptions!C59 -> 48000 | AF35: =Assumptions!C59 -> 48000 | AG35: =Assumptions!C59 -> 48000 | AH35: =Assumptions!C59 -> 48000 | AI35: =Assumptions!C59 -> 48000 | AJ35: =Assumptions!C59 -> 48000 | AK35: =Assumptions!C59 -> 48000 | AL35: =SUM(B35:M35) -> 74000 | AM35: =SUM(N35:Y35) -> 360000 | AN35: =SUM(Z35:AK35) -> 576000
A36: Marketing (content/tools base + paid social) | B36: =Assumptions!C60 -> 1200 | C36: =Assumptions!C60 -> 1200 | D36: =Assumptions!C60 -> 1200 | E36: =Assumptions!C60+Assumptions!C12 -> 10200 | F36: =Assumptions!C60+Assumptions!C12 -> 10200 | G36: =Assumptions!C60+Assumptions!C12 -> 10200 | H36: =Assumptions!C60+Assumptions!C12 -> 10200 | I36: =Assumptions!C60+Assumptions!C12 -> 10200 | J36: =Assumptions!C60+Assumptions!C12 -> 10200 | K36: =Assumptions!C60+Assumptions!C12 -> 10200 | L36: =Assumptions!C60+Assumptions!C12 -> 10200 | M36: =Assumptions!C60+Assumptions!C12 -> 10200 | N36: =Assumptions!C61+Assumptions!C13 -> 20000 | O36: =Assumptions!C61+Assumptions!C13 -> 20000 | P36: =Assumptions!C61+Assumptions!C13 -> 20000 | Q36: =Assumptions!C61+Assumptions!C13 -> 20000 | R36: =Assumptions!C61+Assumptions!C13 -> 20000 | S36: =Assumptions!C61+Assumptions!C13 -> 20000 | T36: =Assumptions!C61+Assumptions!C13 -> 20000 | U36: =Assumptions!C61+Assumptions!C13 -> 20000 | V36: =Assumptions!C61+Assumptions!C13 -> 20000 | W36: =Assumptions!C61+Assumptions!C13 -> 20000 | X36: =Assumptions!C61+Assumptions!C13 -> 20000 | Y36: =Assumptions!C61+Assumptions!C13 -> 20000 | Z36: =Assumptions!C62+Assumptions!C14 -> 21000 | AA36: =Assumptions!C62+Assumptions!C14 -> 21000 | AB36: =Assumptions!C62+Assumptions!C14 -> 21000 | AC36: =Assumptions!C62+Assumptions!C14 -> 21000 | AD36: =Assumptions!C62+Assumptions!C14 -> 21000 | AE36: =Assumptions!C62+Assumptions!C14 -> 21000 | AF36: =Assumptions!C62+Assumptions!C14 -> 21000 | AG36: =Assumptions!C62+Assumptions!C14 -> 21000 | AH36: =Assumptions!C62+Assumptions!C14 -> 21000 | AI36: =Assumptions!C62+Assumptions!C14 -> 21000 | AJ36: =Assumptions!C62+Assumptions!C14 -> 21000 | AK36: =Assumptions!C62+Assumptions!C14 -> 21000 | AL36: =SUM(B36:M36) -> 95400 | AM36: =SUM(N36:Y36) -> 240000 | AN36: =SUM(Z36:AK36) -> 252000
A37: Clinical partnerships (cost) | B37: =0 -> 0 | C37: =0 -> 0 | D37: =Assumptions!C63 -> 900 | E37: =Assumptions!C63 -> 900 | F37: =Assumptions!C63 -> 900 | G37: =Assumptions!C63 -> 900 | H37: =Assumptions!C63 -> 900 | I37: =Assumptions!C63 -> 900 | J37: =Assumptions!C63 -> 900 | K37: =Assumptions!C63 -> 900 | L37: =Assumptions!C63 -> 900 | M37: =Assumptions!C63 -> 900 | N37: =Assumptions!C64 -> 1500 | O37: =Assumptions!C64 -> 1500 | P37: =Assumptions!C64 -> 1500 | Q37: =Assumptions!C64 -> 1500 | R37: =Assumptions!C64 -> 1500 | S37: =Assumptions!C64 -> 1500 | T37: =Assumptions!C64 -> 1500 | U37: =Assumptions!C64 -> 1500 | V37: =Assumptions!C64 -> 1500 | W37: =Assumptions!C64 -> 1500 | X37: =Assumptions!C64 -> 1500 | Y37: =Assumptions!C64 -> 1500 | Z37: =Assumptions!C65 -> 2200 | AA37: =Assumptions!C65 -> 2200 | AB37: =Assumptions!C65 -> 2200 | AC37: =Assumptions!C65 -> 2200 | AD37: =Assumptions!C65 -> 2200 | AE37: =Assumptions!C65 -> 2200 | AF37: =Assumptions!C65 -> 2200 | AG37: =Assumptions!C65 -> 2200 | AH37: =Assumptions!C65 -> 2200 | AI37: =Assumptions!C65 -> 2200 | AJ37: =Assumptions!C65 -> 2200 | AK37: =Assumptions!C65 -> 2200 | AL37: =SUM(B37:M37) -> 9000 | AM37: =SUM(N37:Y37) -> 18000 | AN37: =SUM(Z37:AK37) -> 26400
A38: Legal & admin | B38: =Assumptions!C66 -> 800 | C38: =Assumptions!C66 -> 800 | D38: =Assumptions!C66 -> 800 | E38: =Assumptions!C67 -> 350 | F38: =Assumptions!C67 -> 350 | G38: =Assumptions!C67 -> 350 | H38: =Assumptions!C67 -> 350 | I38: =Assumptions!C67 -> 350 | J38: =Assumptions!C67 -> 350 | K38: =Assumptions!C67 -> 350 | L38: =Assumptions!C67 -> 350 | M38: =Assumptions!C67 -> 350 | N38: =Assumptions!C67 -> 350 | O38: =Assumptions!C67 -> 350 | P38: =Assumptions!C67 -> 350 | Q38: =Assumptions!C67 -> 350 | R38: =Assumptions!C67 -> 350 | S38: =Assumptions!C67 -> 350 | T38: =Assumptions!C67 -> 350 | U38: =Assumptions!C67 -> 350 | V38: =Assumptions!C67 -> 350 | W38: =Assumptions!C67 -> 350 | X38: =Assumptions!C67 -> 350 | Y38: =Assumptions!C67 -> 350 | Z38: =Assumptions!C67 -> 350 | AA38: =Assumptions!C67 -> 350 | AB38: =Assumptions!C67 -> 350 | AC38: =Assumptions!C67 -> 350 | AD38: =Assumptions!C67 -> 350 | AE38: =Assumptions!C67 -> 350 | AF38: =Assumptions!C67 -> 350 | AG38: =Assumptions!C67 -> 350 | AH38: =Assumptions!C67 -> 350 | AI38: =Assumptions!C67 -> 350 | AJ38: =Assumptions!C67 -> 350 | AK38: =Assumptions!C67 -> 350 | AL38: =SUM(B38:M38) -> 5550 | AM38: =SUM(N38:Y38) -> 4200 | AN38: =SUM(Z38:AK38) -> 4200
A39: HealthKit + Health Connect build (M4–6, one-off) | B39: =0 -> 0 | C39: =0 -> 0 | D39: =0 -> 0 | E39: =Assumptions!C50/3 -> 2666.6667 | F39: =Assumptions!C50/3 -> 2666.6667 | G39: =Assumptions!C50/3 -> 2666.6667 | H39: =0 -> 0 | I39: =0 -> 0 | J39: =0 -> 0 | K39: =0 -> 0 | L39: =0 -> 0 | M39: =0 -> 0 | N39: =0 -> 0 | O39: =0 -> 0 | ... AK39: =0 -> 0 | AL39: =SUM(B39:M39) -> 8000 | AM39: =SUM(N39:Y39) -> 0 | AN39: =SUM(Z39:AK39) -> 0
A40: Oura Ring integration (M15, one-off) | B40: =0 -> 0 | C40: =0 -> 0 | D40: =0 -> 0 | E40: =0 -> 0 | F40: =0 -> 0 | G40: =0 -> 0 | H40: =0 -> 0 | I40: =0 -> 0 | ... O40: =0 -> 0 | P40: =Assumptions!C51 -> 5000 | Q40: =0 -> 0 | R40: =0 -> 0 | S40: =0 -> 0 | T40: =0 -> 0 | U40: =0 -> 0 | V40: =0 -> 0 | W40: =0 -> 0 | X40: =0 -> 0 | ... AK40: =0 -> 0 | AL40: =SUM(B40:M40) -> 0 | AM40: =SUM(N40:Y40) -> 5000 | AN40: =SUM(Z40:AK40) -> 0
A41: Predictive AI dev (M20–M23, €3K/mo) | B41: =0 -> 0 | C41: =0 -> 0 | D41: =0 -> 0 | E41: =0 -> 0 | F41: =0 -> 0 | G41: =0 -> 0 | H41: =0 -> 0 | I41: =0 -> 0 | ... T41: =0 -> 0 | U41: =Assumptions!C52 -> 3000 | V41: =Assumptions!C52 -> 3000 | W41: =Assumptions!C52 -> 3000 | X41: =Assumptions!C52 -> 3000 | Y41: =0 -> 0 | Z41: =0 -> 0 | AA41: =0 -> 0 | AB41: =0 -> 0 | AC41: =0 -> 0 | AD41: =0 -> 0 | AE41: =0 -> 0 | AF41: =0 -> 0 | ... AK41: =0 -> 0 | AL41: =SUM(B41:M41) -> 0 | AM41: =SUM(N41:Y41) -> 12000 | AN41: =SUM(Z41:AK41) -> 0
A42: TOTAL COSTS | B42: =B30+B31+B32+B33+B34+B35+B36+B37+B38+B39+B40+B41 -> 3008.7424 | C42: =C30+C31+C32+C33+C34+C35+C36+C37+C38+C39+C40+C41 -> 3024.407 | D42: =D30+D31+D32+D33+D34+D35+D36+D37+D38+D39+D40+D41 -> 9524.8168 | E42: =E30+E31+E32+E33+E34+E35+E36+E37+E38+E39+E40+E41 -> 21134.733 | F42: =F30+F31+F32+F33+F34+F35+F36+F37+F38+F39+F40+F41 -> 21673.476 | G42: =G30+G31+G32+G33+G34+G35+G36+G37+G38+G39+G40+G41 -> 22828.081 | H42: =H30+H31+H32+H33+H34+H35+H36+H37+H38+H39+H40+H41 -> 24774.884 | I42: =I30+I31+I32+I33+I34+I35+I36+I37+I38+I39+I40+I41 -> 25363.299 | ... AK42: =AK30+AK31+AK32+AK33+AK34+AK35+AK36+AK37+AK38+AK39+AK40+AK41 -> 213059.03 | AL42: =SUM(B42:M42) -> 238396.68 | AM42: =SUM(N42:Y42) -> 917121.47 | AN42: =SUM(Z42:AK42) -> 1847170.5
...

Sheet Realistic
A1: NutriSync — Realistic Scenario | All inputs from Assumptions sheet | Blue = inputs, Black = formulas
A2: METRIC | B2: M1 | C2: M2 | D2: M3 | E2: M4 | F2: M5 | G2: M6 | H2: M7 | I2: M8 | J2: M9 | K2: M10 | L2: M11 | M2: M12 | N2: M13 | O2: M14 | P2: M15 | Q2: M16 | R2: M17 | S2: M18 | T2: M19 | U2: M20 | V2: M21 | W2: M22 | X2: M23 | Y2: M24 | Z2: M25 | AA2: M26 | AB2: M27 | AC2: M28 | AD2: M29 | AE2: M30 | AF2: M31 | AG2: M32 | AH2: M33 | AI2: M34 | AJ2: M35 | AK2: M36 | AL2: Y1 Total | AM2: Y2 Total | AN2: Y3 Total | AO2: Notes / Formula
A3: Year | B3: 1 | C3: 1 | D3: 1 | E3: 1 | F3: 1 | G3: 1 | H3: 1 | I3: 1 | J3: 1 | K3: 1 | L3: 1 | M3: 1 | N3: 2 | O3: 2 | P3: 2 | Q3: 2 | R3: 2 | S3: 2 | T3: 2 | U3: 2 | V3: 2 | W3: 2 | X3: 2 | Y3: 2 | Z3: 3 | AA3: 3 | AB3: 3 | AC3: 3 | AD3: 3 | AE3: 3 | AF3: 3 | AG3: 3 | AH3: 3 | AI3: 3 | AJ3: 3 | AK3: 3
A4: SECTION 1 — USER PROJECTIONS
A5: New organic free users/mo | B5: =Assumptions!D9 -> 350 | C5: =B5*(1+Assumptions!D10) -> 416.5 | D5: =C5*(1+Assumptions!D10) -> 495.635 | E5: =D5*(1+Assumptions!D10) -> 589.80565 | F5: =E5*(1+Assumptions!D10) -> 701.86872 | G5: =F5*(1+Assumptions!D10) -> 835.22378 | H5: =G5*(1+Assumptions!D10) -> 993.9163 | I5: =H5*(1+Assumptions!D10) -> 1182.7604 | J5: =I5*(1+Assumptions!D10) -> 1407.4849 | K5: =J5*(1+Assumptions!D10) -> 1674.907 | L5: =K5*(1+Assumptions!D10) -> 1993.1393 | M5: =L5*(1+Assumptions!D10) -> 2371.8358 | N5: =M5*(1+Assumptions!D10) -> 2822.4846 | O5: =N5*(1+Assumptions!D10) -> 3358.7567 | P5: =O5*(1+Assumptions!D10) -> 3996.9204 | Q5: =P5*(1+Assumptions!D10) -> 4756.3353 | R5: =Q5*(1+Assumptions!D10) -> 5660.039 | S5: =R5*(1+Assumptions!D10) -> 6735.4465 | T5: =S5*(1+Assumptions!D10) -> 8015.1813 | U5: =T5*(1+Assumptions!D10) -> 9538.0657 | V5: =U5*(1+Assumptions!D10) -> 11350.298 | W5: =V5*(1+Assumptions!D10) -> 13506.855 | X5: =W5*(1+Assumptions!D10) -> 16073.157 | Y5: =X5*(1+Assumptions!D10) -> 19127.057 | Z5: =Y5*(1+Assumptions!D10) -> 22761.198 | AA5: =Z5*(1+Assumptions!D10) -> 27085.826 | AB5: =AA5*(1+Assumptions!D10) -> 32232.133 | AC5: =AB5*(1+Assumptions!D10) -> 38356.238 | AD5: =AC5*(1+Assumptions!D10) -> 45643.923 | AE5: =AD5*(1+Assumptions!D10) -> 54316.268 | AF5: =AE5*(1+Assumptions!D10) -> 64636.359 | AG5: =AF5*(1+Assumptions!D10) -> 76917.268 | AH5: =AG5*(1+Assumptions!D10) -> 91531.548 | AI5: =AH5*(1+Assumptions!D10) -> 108922.54 | AJ5: =AI5*(1+Assumptions!D10) -> 129617.83 | AK5: =AJ5*(1+Assumptions!D10) -> 154245.21 | AL5: =SUM(B5:M5) -> 13013.077 | AM5: =SUM(N5:Y5) -> 104940.6 | AN5: =SUM(Z5:AK5) -> 846266.34 | AO5: Compounds from M1 at organic growth rate.
A6: → New paid: organic conversion (one-off per month's new free users) | B6: =B5*Assumptions!D11 -> 49 | C6: =C5*Assumptions!D11 -> 58.31 | D6: =D5*Assumptions!D11 -> 69.3889 | E6: =E5*Assumptions!D11 -> 82.572791 | F6: =F5*Assumptions!D11 -> 98.261621 | G6: =G5*Assumptions!D11 -> 116.93133 | H6: =H5*Assumptions!D11 -> 139.14828 | I6: =I5*Assumptions!D11 -> 165.58646 | J6: =J5*Assumptions!D11 -> 197.04788 | K6: =K5*Assumptions!D11 -> 234.48698 | L6: =L5*Assumptions!D11 -> 279.03951 | M6: =M5*Assumptions!D11 -> 332.05701 | N6: =N5*Assumptions!D11 -> 395.14784 | O6: =O5*Assumptions!D11 -> 470.22593 | P6: =P5*Assumptions!D11 -> 559.56886 | Q6: =Q5*Assumptions!D11 -> 665.88695 | R6: =R5*Assumptions!D11 -> 792.40547 | S6: =S5*Assumptions!D11 -> 942.9625 | T6: =T5*Assumptions!D11 -> 1122.1254 | U6: =U5*Assumptions!D11 -> 1335.3292 | V6: =V5*Assumptions!D11 -> 1589.0418 | W6: =W5*Assumptions!D11 -> 1890.9597 | X6: =X5*Assumptions!D11 -> 2250.242 | Y6: =Y5*Assumptions!D11 -> 2677.788 | Z6: =Z5*Assumptions!D11 -> 3186.5677 | AA6: =AA5*Assumptions!D11 -> 3792.0156 | AB6: =AB5*Assumptions!D11 -> 4512.4986 | AC6: =AC5*Assumptions!D11 -> 5369.8733 | AD6: =AD5*Assumptions!D11 -> 6390.1492 | AE6: =AE5*Assumptions!D11 -> 7604.2776 | AF6: =AF5*Assumptions!D11 -> 9049.0903 | AG6: =AG5*Assumptions!D11 -> 10768.417 | AH6: =AH5*Assumptions!D11 -> 12814.417 | AI6: =AI5*Assumptions!D11 -> 15249.156 | AJ6: =AJ5*Assumptions!D11 -> 18146.496 | AK6: =AK5*Assumptions!D11 -> 21594.33 | AL6: =SUM(B6:M6) -> 1821.8308 | AM6: =SUM(N6:Y6) -> 14691.684 | AN6: =SUM(Z6:AK6) -> 118477.29 | AO6: 5–8% one-off per month (NOT monthly to pool). Benchmark: RevenueCat H&F median 6.9%.
A7: → New paid: paid social (budget ÷ CAC) | B7: =0 -> 0 | C7: =0 -> 0 | D7: =0 -> 0 | E7: =Assumptions!D12/Assumptions!D15 -> 733.33333 | F7: =Assumptions!D12/Assumptions!D15 -> 733.33333 | G7: =Assumptions!D12/Assumptions!D15 -> 733.33333 | H7: =Assumptions!D12/Assumptions!D15 -> 733.33333 | I7: =Assumptions!D12/Assumptions!D15 -> 733.33333 | J7: =Assumptions!D12/Assumptions!D15 -> 733.33333 | K7: =Assumptions!D12/Assumptions!D15 -> 733.33333 | L7: =Assumptions!D12/Assumptions!D15 -> 733.33333 | M7: =Assumptions!D12/Assumptions!D15 -> 733.33333 | N7: =Assumptions!D13/Assumptions!D16 -> 1555.5556 | O7: =Assumptions!D13/Assumptions!D16 -> 1555.5556 | P7: =Assumptions!D13/Assumptions!D16 -> 1555.5556 | Q7: =Assumptions!D13/Assumptions!D16 -> 1555.5556 | R7: =Assumptions!D13/Assumptions!D16 -> 1555.5556 | S7: =Assumptions!D13/Assumptions!D16 -> 1555.5556 | T7: =Assumptions!D13/Assumptions!D16 -> 1555.5556 | U7: =Assumptions!D13/Assumptions!D16 -> 1555.5556 | V7: =Assumptions!D13/Assumptions!D16 -> 1555.5556 | W7: =Assumptions!D13/Assumptions!D16 -> 1555.5556 | X7: =Assumptions!D13/Assumptions!D16 -> 1555.5556 | Y7: =Assumptions!D13/Assumptions!D16 -> 1555.5556 | Z7: =Assumptions!D14/Assumptions!D16 -> 1166.6667 | AA7: =Assumptions!D14/Assumptions!D16 -> 1166.6667 | AB7: =Assumptions!D14/Assumptions!D16 -> 1166.6667 | AC7: =Assumptions!D14/Assumptions!D16 -> 1166.6667 | AD7: =Assumptions!D14/Assumptions!D16 -> 1166.6667 | AE7: =Assumptions!D14/Assumptions!D16 -> 1166.6667 | AF7: =Assumptions!D14/Assumptions!D16 -> 1166.6667 | AG7: =Assumptions!D14/Assumptions!D16 -> 1166.6667 | AH7: =Assumptions!D14/Assumptions!D16 -> 1166.6667 | AI7: =Assumptions!D14/Assumptions!D16 -> 1166.6667 | AJ7: =Assumptions!D14/Assumptions!D16 -> 1166.6667 | AK7: =Assumptions!D14/Assumptions!D16 -> 1166.6667 | AL7: =SUM(B7:M7) -> 6600 | AM7: =SUM(N7:Y7) -> 18666.667 | AN7: =SUM(Z7:AK7) -> 14000 | AO7: Budget / CAC. CAC corrected: €20 Y1 conservative (not €6–8; install alone $3.70–4.70).
